Workbook

Sheet INVOICE FOR USD
A1: ISSUER:XIAMEN SUTE CONSTRUCTION MACHINERY CO., LTD. | K1: INVOICE
A2: Add:No. 1-103, Fengshan West Road, Fengshan Community, Haicang District, Xiamen City, China
A3: Tel: 0086 592 6264338, Fax: 0086 592 5556820, Mob: 0086 18650178968
A4: TO:O.C.R. CO., LTD.
A5: Add2/2 Mu 7,Tambon Klongsai,Amphoe Natawi,Changwat Songkhla 90160,Thailand
A6: Tel:+66 74 255-897,Fax:+66 74 255898
A7: Marks:O.C.R. CO., LTD | H7: INV NO.: ST/OCR26326T1 | K7: DATE:2026-06-30
A8: Ship from: Xiamen China | K8: To: Laem Chabang Thailand
A9: SL | B9: PO NO. | C9: DESCRIPTION | H9: QTY | I9: UNIT | J9: UNIT PRICE | K9: AMOUNT | L9: HS.code | M9: FIGURE NO.
C10: THAI NAME | D10: MAIN MATERIAL | E10: ENGLISH NAME | F10: PART NO. | G10: OCR NO. | J10: USD | K10: USD
A11: TRUCK SPARE PARTS
A12: 1 | B12: PRS260510032 | C12: กล่องควบคุมABS | D12: เหล็ก | E12: ABS CONTROLLER (KEMI) | F12: 453603771/XGA36HKFW211-30201 | G12: XGA4253880300 | H12: 1 | I12: PC | J12: ='INVOICE FOR CNY'!J12/6.79 -> 62.002946 | K12: =H12*J12 -> 62.002946 | L12: 853710 | M12: NO.1
A13: 2 | B13: PRS260510032 | C13: วาล์วรีเลย์4 ทาง | D13: เหล็ก | E13: RELAY VALVE ASSEMBLY | F13: 453502216/NXG3527WLFW6B1-010 | G13: XGA4250778090 | H13: 2 | I13: PCS | J13: ='INVOICE FOR CNY'!J13/6.79 -> 13.843888 | K13: =H13*J13 -> 27.687776 | L13: 848180 | M13: NO.2
A14: 3 | B14: PRS260510032 | C14: ยางกันกระแทกแหนบหน้า | D14: ยาง | E14: LIMIT BLOCK - FRONT SUSPENSION | F14: 452906875/XGA29HEFW211-01106 | G14: XGA4250668020 | H14: 4 | I14: PCS | J14: ='INVOICE FOR CNY'!J14/6.79 -> 2.7982327 | K14: =H14*J14 -> 11.192931 | L14: 401699 | M14: NO.3
A15: 4 | B15: PRS260510032 | C15: สกรูจับสลักโตงเตงแหนบหน้า | D15: เหล็ก | E15: SPRING PIN LOCATING BOLT | F15: 452902661/NXG29KFW111-01054 | G15: XGA3252980100 | H15: 10 | I15: PCS | J15: ='INVOICE FOR CNY'!J15/6.79 -> 0.44182622 | K15: =H15*J15 -> 4.4182622 | L15: 731815 | M15: NO.4
A16: 5 | B16: PRS260510032 | C16: สายสลิงล็อคก้ามเบรค(สั้น) | D16: เหล็ก | E16: WEAR ALARM JUMPER WIRE | F16: 459306729/HD90009580001 | G16: XGA3252802610 | H16: 2 | I16: PCS | J16: ='INVOICE FOR CNY'!J16/6.79 -> 7.5110457 | K16: =H16*J16 -> 15.022091 | L16: 731210 | M16: NO.5
A17: 6 | B17: PRS260510032 | C17: น็อตจับข้อต่อสายลม | D17: เหล็ก | E17: INTERNAL SERRATED LOCKING WASHER | F17: 805339139 + 453502192 | G17: XGA3252112202 | H17: 5 | I17: PCS | J17: ='INVOICE FOR CNY'!J17/6.79 -> 6.4801178 | K17: =H17*J17 -> 32.400589 | L17: 731815 | M17: NO.6
A18: 7 | B18: PRS260510032 | C18: ข้อต่อวาล์ว | D18: เหล็ก | E18: END TYPE CONNECTOR+SEAL WASHER | F18: 453505137 + 805339161 | G18: XGA3250426060 | H18: 20 | I18: PCS | J18: ='INVOICE FOR CNY'!J18/6.79 -> 1.6200295 | K18: =H18*J18 -> 32.400589 | L18: 732690 | M18: NO.7
A19: 8 | B19: PRS260510032 | C19: ข้อต่อวาล์ว(ตรง) | D19: เหล็ก | E19: HOLLOW BOLT+CIRCLIP+SPECIAL SECTION SEAL | F19: 453505138 + 453505139 + 453505140 | G19: XGA3250424070 | H19: 20 | I19: PCS | J19: ='INVOICE FOR CNY'!J19/6.79 -> 1.7673049 | K19: =H19*J19 -> 35.346097 | L19: 732690 | M19: NO.8
A20: 9 | B20: PRS260510032 | C20: ข้อต่อ(ตรง)หางไหลหม้อน้ำลมเบรค | D20: เหล็ก | E20: HOLLOW BOLT+CIRCLIP+SPECIAL SECTION SEAL | F20: 453505131 + 453505132 + 453505133 | G20: XGA3250416010 | H20: 50 | I20: PCS | J20: ='INVOICE FOR CNY'!J20/6.79 -> 1.9145803 | K20: =H20*J20 -> 95.729013 | L20: 732690 | M20: NO.9
A21: 10 | B21: PRS260510032 | C21: โช๊คอัพ | D21: เหล็ก | E21: SHOCK ABSORBER ASSEMBLY | F21: 452906971/XGA2921YPAY132-010 | G21: XGA3250376010 | H21: 4 | I21: PCS | J21: ='INVOICE FOR CNY'!J21/6.79 -> 21.649485 | K21: =H21*J21 -> 86.597938 | L21: 870880 | M21: NO.10
A22: 11 | B22: PRS260510032 | C22: ขอบบังโคลนหน้าซ้าย | D22: เหล็ก | E22: LEFT FRONT FENDER ASSEMBLY | F22: 4584002159 | G22: XGA1150990400 | H22: 2 | I22: PCS | J22: ='INVOICE FOR CNY'!J22/6.79 -> 15.463918 | K22: =H22*J22 -> 30.927835 | L22: 732690 | M22: NO.11
A23: 12 | B23: PRS260510032 | C23: ขอบบังโคลนหน้าขวา | D23: เหล็ก | E23: RIGHT FRONT FENDER ASSEMBLY | F23: 4584002158 | G23: XGA1150990100 | H23: 2 | I23: PCS | J23: ='INVOICE FOR CNY'!J23/6.79 -> 15.463918 | K23: =H23*J23 -> 30.927835 | L23: 732690 | M23: NO.12
A24: 13 | B24: PRS260510032 | C24: เซ็นเซอร์อุณหภูมิ | D24: เหล็ก | E24: OUTDOOR TEMPERATURE SENSOR | F24: 458108684/XGA81AMSE111-030500 | G24: XGA1150690600 | H24: 2 | I24: PCS | J24: ='INVOICE FOR CNY'!J24/6.79 -> 2.5036819 | K24: =H24*J24 -> 5.0073638 | L24: 853690 | M24: NO.13
A25: 14 | B25: PRS260510032 | C25: ชุดกระจังหน้า | D25: เหล็ก | E25: FRONT GRILLE ASSEMBLY INCLUDE FRONT LOGO ASSEMBLY | F25: 453906704 + 455312866 | G25: XGA1150690400 | H25: 3 | I25: PCS | J25: ='INVOICE FOR CNY'!J25/6.79 -> 73.932253 | K25: =H25*J25 -> 221.79676 | L25: 732690 | M25: NO.14
A26: 15 | B26: PRS260510032 | C26: แผงหน้าปัด | D26: เหล็ก | E26: FRONT PANEL ASSEMBLY | F26: 4553006658 | G26: XGA1150670200 | H26: 2 | I26: PCS | J26: ='INVOICE FOR CNY'!J26/6.79 -> 53.755523 | K26: =H26*J26 -> 107.51105 | L26: 853710 | M26: NO.15
A27: 16 | B27: PRS260510032 | C27: แก้มหน้าขวา | D27: เหล็ก | E27: RIGHT SIDE TRIM ASSEMBLY | F27: 4553006662 | G27: XGA1150670100 | H27: 2 | I27: PCS | J27: ='INVOICE FOR CNY'!J27/6.79 -> 22.680412 | K27: =H27*J27 -> 45.360825 | L27: 870829 | M27: NO.16
A28: 17 | B28: PRS260510032 | C28: ชุดลิมิตเตอร์ | D28: เหล็ก | E28: LIMITER ASSEMBLY | F28: 455019938/XGA50XEAW591-02111 | G28: XGA1150550700 | H28: 2 | I28: PCS | J28: ='INVOICE FOR CNY'!J28/6.79 -> 9.2783505 | K28: =H28*J28 -> 18.556701 | L28: 853650 | M28: NO.17
A29: 18 | B29: PRS260510032 | C29: เซ็นเซอร์แรงดันอากาศ | D29: เหล็ก | E29: AIR PRESSURE SENSOR | F29: 453808374/38HKFW211-30010 | G29: XGA1150457020 | H29: 4 | I29: PCS | J29: ='INVOICE FOR CNY'!J29/6.79 -> 10.162003 | K29: =H29*J29 -> 40.648012 | L29: 853690 | M29: NO.18
A30: 19 | B30: PRS260510032 | C30: แผงคอยล์ร้อน | D30: เหล็ก | E30: CONDENSER ASSEMBLY | F30: 458108700/XGA81AMSE111-050100_ | G30: XGA1150439030 | H30: 3 | I30: PCS | J30: ='INVOICE FOR CNY'!J30/6.79 -> 43.004418 | K30: =H30*J30 -> 129.01325 | L30: 732690 | M30: NO.19
A31: 20 | B31: PRS260510032 | C31: ท่อแรงดันต่ำสามทางถึงคอยล์เย็น | D31: เหล็ก | E31: LOW PRESSURE PIPE - T-JUNCTION TO EVAPORATOR SECTION | F31: 4581007526 | G31: XGA1150431140 | H31: 3 | I31: PCS | J31: ='INVOICE FOR CNY'!J31/6.79 -> 13.254786 | K31: =H31*J31 -> 39.764359 | L31: 400921 | M31: NO.20
A32: 21 | B32: PRS260510032 | C32: สายจากคอนโทรลมือเข้าวาล์วแรงดัน | D32: เหล็ก | E32: HIGH-PRESSURE PIPE – VALVE STEAM SECTION | F32: 4581007525 | G32: XGA1150431100 | H32: 3 | I32: PCS | J32: ='INVOICE FOR CNY'!J32/6.79 -> 10.603829 | K32: =H32*J32 -> 31.811487 | L32: 854430 | M32: NO.21
A33: 22 | B33: PRS260510032 | C33: ท่อแรงดันสูงวาล์วความเย็น | D33: เหล็ก | E33: HIGH PRESSURE PIPE - COOLING VALVE SECTION | F33: 4581007527 | G33: XGA1150431090 | H33: 3 | I33: PCS | J33: ='INVOICE FOR CNY'!J33/6.79 -> 10.162003 | K33: =H33*J33 -> 30.486009 | L33: 400921 | M33: NO.22
A34: 23 | B34: PRS260510032 | C34: ช่องเสียบ USB | D34: เหล็ก | E34: USB INTERFACE | F34: 453717729/XGA37AMSN111-260200 | G34: XGA1150411030 | H34: 3 | I34: PCS | J34: ='INVOICE FOR CNY'!J34/6.79 -> 7.5110457 | K34: =H34*J34 -> 22.533137 | L34: 853690 | M34: NO.23
A35: 24 | B35: PRS260510032 | C35: ช่องจ่ายไฟ | D35: เหล็ก | E35: 24V POWER OUTLET | F35: 453717739/XGA37AMSN111-260400 | G35: XGA1150411020 | H35: 3 | I35: PCS | J35: ='INVOICE FOR CNY'!J35/6.79 -> 1.3254786 | K35: =H35*J35 -> 3.9764359 | L35: 853690 | M35: NO.24
A36: 25 | B36: PRS260510032 | C36: ชุดสวิทซ์เปิด-ปิดกระจก | D36: เหล็ก | E36: ELECTRIC WINDOW MAIN SWITCH | F36: 453719236/XGA37AKSE111-460100 | G36: XGA1150399010 | H36: 3 | I36: PCS | J36: ='INVOICE FOR CNY'!J36/6.79 -> 4.712813 | K36: =H36*J36 -> 14.138439 | L36: 853710 | M36: NO.25
A37: 26 | B37: PRS260510032 | C37: สวิทช์เกียร์ | D37: เหล็ก | E37: INTER-WHEEL DIFFERENTIAL LOCK SWITCH | F37: 459357670/XGA37AKSE111-920190 | G37: XGA1150387090 | H37: 5 | I37: PCS | J37: ='INVOICE FOR CNY'!J37/6.79 -> 1.9145803 | K37: =H37*J37 -> 9.5729013 | L37: 853710 | M37: NO.26
A38: 27 | B38: PRS260510032 | C38: สวิทซ์เปิด-ปิดสัญญาณ | D38: เหล็ก | E38: LOW SPEED ALARM OFF SWITCH | F38: 459355728/ XGA37AKSE321-920210 | G38: XGA1150387080 | H38: 5 | I38: PCS | J38: ='INVOICE FOR CNY'!J38/6.79 -> 2.2091311 | K38: =H38*J38 -> 11.045655 | L38: 853710 | M38: NO.27
A39: 28 | B39: PRS260510032 | C39: ข้อต่อไฮดรอลิค | D39: เหล็ก | E39: COMPRESSION FITTING PARTITIONED RIGHT ANGLE CONNECTOR BODY | F39: 819958812/Q81412 | G39: XGA1150357010 | H39: 20 | I39: PCS | J39: ='INVOICE FOR CNY'!J39/6.79 -> 1.1782032 | K39: =H39*J39 -> 23.564065 | L39: 732690 | M39: NO.28
A40: 29 | B40: PRS260510032 | C40: ท่อกรองอากาศปั้มลมเข้าปั้มลม | D40: เหล็ก | E40: HIGH-TEMPERATURE RESISTANT PIPE ASSEMBLY | F40: 4535004234 | G40: XGA1150351010 | H40: 2 | I40: PCS | J40: ='INVOICE FOR CNY'!J40/6.79 -> 9.4256259 | K40: =H40*J40 -> 18.851252 | L40: 400921 | M40: NO.29
...

Sheet INVOICE FOR CNY
A1: ISSUER:XIAMEN SUTE CONSTRUCTION MACHINERY CO., LTD. | K1: INVOICE
A2: Add:No. 1-103, Fengshan West Road, Fengshan Community, Haicang District, Xiamen City, China
A3: Tel: 0086 592 6264338, Fax: 0086 592 5556820, Mob: 0086 18650178968
A4: TO:O.C.R. CO., LTD.
A5: Add2/2 Mu 7,Tambon Klongsai,Amphoe Natawi,Changwat Songkhla 90160,Thailand
A6: Tel:+66 74 255-897,Fax:+66 74 255898
A7: Marks:O.C.R. CO., LTD | H7: INV NO.: ST/OCR26326T1 | K7: DATE:2026-06-30
A8: Ship from: Xiamen China | K8: To: Laem Chabang Thailand
A9: DESCRIPTION | H9: QTY | I9: UNIT | J9: UNIT PRICE | K9: AMOUNT | L9: HS.code | M9: FIGURE NO.
A10: SL | B10: PR NO. | C10: THAI NAME | D10: MATERIAL | E10: ENGLISH NAME | F10: PART NO. | G10: OCR NO. | J10: CNY | K10: CNY
A11: TRUCK SPARE PARTS
A12: 1 | B12: PRS260510032 | C12: กล่องควบคุมABS | D12: เหล็ก | E12: ABS CONTROLLER (KEMI) | F12: 453603771/XGA36HKFW211-30201 | G12: XGA4253880300 | H12: 1 | I12: PC | J12: 421 | K12: =H12*J12 -> 421 | L12: 853710 | M12: NO.1
A13: 2 | B13: PRS260510032 | C13: วาล์วรีเลย์4 ทาง | D13: เหล็ก | E13: RLAY VALVE ASSEMBLY | F13: 453502216/NXG3527WLFW6B1-010 | G13: XGA4250778090 | H13: 2 | I13: PCS | J13: 94 | K13: =H13*J13 -> 188 | L13: 848180 | M13: NO.2
A14: 3 | B14: PRS260510032 | C14: ยางกันกระแทกแหนบหน้า | D14: ยาง | E14: LIMIT BLOCK - FRONT SUSPENSION | F14: 452906875/XGA29HEFW211-01106 | G14: XGA4250668020 | H14: 4 | I14: PCS | J14: 19 | K14: =H14*J14 -> 76 | L14: 401699 | M14: NO.3
A15: 4 | B15: PRS260510032 | C15: สกรูจับสลักโตงเตงแหนบหน้า | D15: เหล็ก | E15: SPRING PIN LOCATING BOLT | F15: 452902661/NXG29KFW111-01054 | G15: XGA3252980100 | H15: 10 | I15: PCS | J15: 3 | K15: =H15*J15 -> 30 | L15: 731815 | M15: NO.4
A16: 5 | B16: PRS260510032 | C16: สายสลิงล็อคก้ามเบรค(สั้น) | D16: เหล็ก | E16: WEAR ALARM JUMPER WIRE | F16: 459306729/HD90009580001 | G16: XGA3252802610 | H16: 2 | I16: PCS | J16: 51 | K16: =H16*J16 -> 102 | L16: 731210 | M16: NO.5
A17: 6 | B17: PRS260510032 | C17: น็อตจับข้อต่อสายลม | D17: เหล็ก | E17: INTERNAL SERRATED LOCKING WASHER | F17: 805339139 | G17: XGA3252112202 | H17: 5 | I17: PCS | J17: 44 | K17: =H17*J17 -> 220 | L17: 731815 | M17: NO.6
A18: 7 | B18: PRS260510032 | C18: ข้อต่อวาล์ว | D18: เหล็ก | E18: END TYPE CONNECTOR+SEAL WASHER | F18: 453505137 + 805339161 | G18: XGA3250426060 | H18: 20 | I18: PCS | J18: 11 | K18: =H18*J18 -> 220 | L18: 732690 | M18: NO.7
A19: 8 | B19: PRS260510032 | C19: ข้อต่อวาล์ว(ตรง) | D19: เหล็ก | E19: HOLLOW BOLT+CIRCLIP+SPECIAL SECTION SEAL | F19: 453505138 + 453505139 + 453505140 | G19: XGA3250424070 | H19: 20 | I19: PCS | J19: 12 | K19: =H19*J19 -> 240 | L19: 732690 | M19: NO.8
A20: 9 | B20: PRS260510032 | C20: ข้อต่อ(ตรง)หางไหลหม้อน้ำลมเบรค | D20: เหล็ก | E20: HOLLOW BOLT+CIRCLIP+SPECIAL SECTION SEAL | F20: 453505131 + 453505132 + 453505133 | G20: XGA3250416010 | H20: 50 | I20: PCS | J20: 13 | K20: =H20*J20 -> 650 | L20: 732690 | M20: NO.9
A21: 10 | B21: PRS260510032 | C21: โช๊คอัพ | D21: เหล็ก | E21: SHOCK ABSORBER ASSEMBLY | F21: 452906971/XGA2921YPAY132-010 | G21: XGA3250376010 | H21: 4 | I21: PCS | J21: 147 | K21: =H21*J21 -> 588 | L21: 870880 | M21: NO.10
A22: 11 | B22: PRS260510032 | C22: ขอบบังโคลนหน้าซ้าย | D22: เหล็ก | E22: LEFT FRONT FENDER ASSEMBLY | F22: 4584002159 | G22: XGA1150990400 | H22: 2 | I22: PCS | J22: 105 | K22: =H22*J22 -> 210 | L22: 732690 | M22: NO.11
A23: 12 | B23: PRS260510032 | C23: ขอบบังโคลนหน้าขวา | D23: เหล็ก | E23: RIGHT FRONT FENDER ASSEMBLY | F23: 4584002158 | G23: XGA1150990100 | H23: 12 | I23: PCS | J23: 105 | K23: =H23*J23 -> 1260 | L23: 732690 | M23: NO.12
A24: 13 | B24: PRS260510032 | C24: เซ็นเซอร์อุณหภูมิ | D24: เหล็ก | E24: OUTDOOR TEMPERATURE SENSOR | F24: 458108684/XGA81AMSE111-030500 | G24: XGA1150690600 | H24: 2 | I24: PCS | J24: 17 | K24: =H24*J24 -> 34 | L24: 853690 | M24: NO.13
A25: 14 | B25: PRS260510032 | C25: ชุดกระจังหน้า | D25: เหล็ก | E25: FRONT GRILLE ASSEMBLY INCLUDE FRONT LOGO ASSEMBLY | F25: 453906704 + 455312866 | G25: XGA1150690400 | H25: 3 | I25: PCS | J25: 502 | K25: =H25*J25 -> 1506 | L25: 732690 | M25: NO.14
A26: 15 | B26: PRS260510032 | C26: แผงหน้าปัด | D26: เหล็ก | E26: FRONT PANEL ASSEMBLY | F26: 4553006658 | G26: XGA1150670200 | H26: 2 | I26: PCS | J26: 365 | K26: =H26*J26 -> 730 | L26: 853710 | M26: NO.15
A27: 16 | B27: PRS260510032 | C27: แก้มหน้าขวา | D27: เหล็ก | E27: RIGHT SIDE TRIM ASSEMBLY | F27: 4553006662 | G27: XGA1150670100 | H27: 2 | I27: PCS | J27: 154 | K27: =H27*J27 -> 308 | L27: 870829 | M27: NO.16
A28: 17 | B28: PRS260510032 | C28: ชุดลิมิตเตอร์ | D28: เหล็ก | E28: LIMITER ASSEMBLY | F28: 455019938/XGA50XEAW591-02111 | G28: XGA1150550700 | H28: 2 | I28: PCS | J28: 63 | K28: =H28*J28 -> 126 | L28: 853651 | M28: NO.17
A29: 18 | B29: PRS260510032 | C29: เซ็นเซอร์แรงดันอากาศ | D29: เหล็ก | E29: AIR PRESSURE SENSOR | F29: 453808374/38HKFW211-30010 | G29: XGA1150457020 | H29: 4 | I29: PCS | J29: 69 | K29: =H29*J29 -> 276 | L29: 853690 | M29: NO.18
A30: 19 | B30: PRS260510032 | C30: แผงคอยล์ร้อน | D30: เหล็ก | E30: CONDENSER ASSEMBLY | F30: 458108700/XGA81AMSE111-050100_ | G30: XGA1150439030 | H30: 3 | I30: PCS | J30: 292 | K30: =H30*J30 -> 876 | L30: 732690 | M30: NO.19
A31: 20 | B31: PRS260510032 | C31: ท่อแรงดันต่ำสามทางถึงคอยล์เย็น | D31: เหล็ก | E31: LOW PRESSURE PIPE - T-JUNCTION TO EVAPORATOR SECTION | F31: 4581007526 | G31: XGA1150431140 | H31: 3 | I31: PCS | J31: 90 | K31: =H31*J31 -> 270 | L31: 400921 | M31: NO.20
A32: 21 | B32: PRS260510032 | C32: สายจากคอนโทรลมือเข้าวาล์วแรงดัน | D32: เหล็ก | E32: HIGH-PRESSURE PIPE – VALVE STEAM SECTION | F32: 4581007525 | G32: XGA1150431100 | H32: 3 | I32: PCS | J32: 72 | K32: =H32*J32 -> 216 | L32: 854430 | M32: NO.21
A33: 22 | B33: PRS260510032 | C33: ท่อแรงดันสูงวาล์วความเย็น | D33: เหล็ก | E33: HIGH PRESSURE PIPE - COOLING VALVE SECTION | F33: 4581007527 | G33: XGA1150431090 | H33: 3 | I33: PCS | J33: 69 | K33: =H33*J33 -> 207 | L33: 400921 | M33: NO.22
A34: 23 | B34: PRS260510032 | C34: ช่องเสียบ USB | D34: เหล็ก | E34: USB INTERFACE | F34: 453717729/XGA37AMSN111-260200 | G34: XGA1150411030 | H34: 3 | I34: PCS | J34: 51 | K34: =H34*J34 -> 153 | L34: 853690 | M34: NO.23
A35: 24 | B35: PRS260510032 | C35: ช่องจ่ายไฟ | D35: เหล็ก | E35: 24V POWER OUTLET | F35: 453717739/XGA37AMSN111-260400 | G35: XGA1150411020 | H35: 3 | I35: PCS | J35: 9 | K35: =H35*J35 -> 27 | L35: 853690 | M35: NO.24
A36: 25 | B36: PRS260510032 | C36: ชุดสวิทซ์เปิด-ปิดกระจก | D36: เหล็ก | E36: ELECTRIC WINDOW MAIN SWITCH | F36: 453719236/XGA37AKSE111-460100 | G36: XGA1150399010 | H36: 3 | I36: PCS | J36: 32 | K36: =H36*J36 -> 96 | L36: 853710 | M36: NO.25
A37: 26 | B37: PRS260510032 | C37: สวิทช์เกียร์ | D37: เหล็ก | E37: INTER-WHEEL DIFFERENTIAL LOCK SWITCH | F37: 459357670/XGA37AKSE111-920190 | G37: XGA1150387090 | H37: 5 | I37: PCS | J37: 13 | K37: =H37*J37 -> 65 | L37: 853710 | M37: NO.26
A38: 27 | B38: PRS260510032 | C38: สวิทซ์เปิด-ปิดสัญญาณ | D38: เหล็ก | E38: LOW SPEED ALARM OFF SWITCH | F38: 459355728/ XGA37AKSE321-920210 | G38: XGA1150387080 | H38: 5 | I38: PCS | J38: 15 | K38: =H38*J38 -> 75 | L38: 853710 | M38: NO.27
A39: 28 | B39: PRS260510032 | C39: ข้อต่อไฮดรอลิค | D39: เหล็ก | E39: COMPRESSION FITTING PARTITIONED RIGHT ANGLE CONNECTOR BODY | F39: 819958812/Q81412 | G39: XGA1150357010 | H39: 20 | I39: PCS | J39: 8 | K39: =H39*J39 -> 160 | L39: 732690 | M39: NO.28
A40: 29 | B40: PRS260510032 | C40: ท่อกรองอากาศปั้มลมเข้าปั้มลม | D40: เหล็ก | E40: HIGH-TEMPERATURE RESISTANT PIPE ASSEMBLY | F40: 4535004234 | G40: XGA1150351010 | H40: 2 | I40: PCS | J40: 64 | K40: =H40*J40 -> 128 | L40: 400921 | M40: NO.29
...

Sheet PACKING LIST
A1: ISSUER:XIAMEN SUTE CONSTRUCTION MACHINERY CO., LTD. | K1: PACKING LIST
A2: Add:No. 1-103, Fengshan West Road, Fengshan Community, Haicang District, Xiamen City, China
A3: Tel: 0086 592 6264338, Fax: 0086 592 5556820, Mob: 0086 18650178968
A4: TO:O.C.R. CO., LTD.
A5: Add2/2 Mu 7,Tambon Klongsai,Amphoe Natawi,Changwat Songkhla 90160,Thailand
A6: Tel:+66 74 255-897,Fax:+66 74 255898
A7: Marks:O.C.R. CO., LTD | H7: INV NO.: ST/OCR26326T1 | K7: DATE:2026-06-30
A8: Ship from: Xiamen China | K8: To: Laem Chabang Thailand
A9: SL | B9: PO NO. | C9: DESCRIPTION | H9: QTY | I9: UNIT | J9: PACKAGE | K9: N.W. | L9: G.W. | M9: MEAS. | N9: CTN. NO.
C10: THAI NAME | D10: MATERIAL | E10: ENGLISH NAME | F10: PART NO. | G10: OCR NO. | K10: KGS | L10: KGS | M10: CBM
A11: TRUCK SPARE PARTS
A12: 1 | B12: PRS260510032 | C12: กล่องควบคุมABS | D12: เหล็ก | E12: ABS CONTROLLER (KEMI) | F12: 453603771/XGA36HKFW211-30201 | G12: XGA4253880300 | H12: 1 | I12: PC | J12: 1 | K12: 0.5 | L12: 0.5 | M12: 0.01 | N12: 001W
A13: 2 | B13: PRS260510032 | C13: วาล์วรีเลย์4 ทาง | D13: เหล็ก | E13: RELAY VALVE ASSEMBLY | F13: 453502216/NXG3527WLFW6B1-010 | G13: XGA4250778090 | H13: 2 | I13: PCS | K13: 2 | L13: 2 | M13: 0.01 | N13: 001W
A14: 3 | B14: PRS260510032 | C14: ยางกันกระแทกแหนบหน้า | D14: ยาง | E14: LIMIT BLOCK - FRONT SUSPENSION | F14: 452906875/XGA29HEFW211-01106 | G14: XGA4250668020 | H14: 4 | I14: PCS | K14: 0.4 | L14: 0.5 | M14: 0.01 | N14: 001W
A15: 4 | B15: PRS260510032 | C15: สกรูจับสลักโตงเตงแหนบหน้า | D15: เหล็ก | E15: SPRING PIN LOCATING BOLT | F15: 452902661/NXG29KFW111-01054 | G15: XGA3252980100 | H15: 10 | I15: PCS | K15: 0.4 | L15: 0.5 | M15: 0.01 | N15: 001W
A16: 5 | B16: PRS260510032 | C16: สายสลิงล็อคก้ามเบรค(สั้น) | D16: เหล็ก | E16: WEAR ALARM JUMPER WIRE | F16: 459306729/HD90009580001 | G16: XGA3252802610 | H16: 2 | I16: PCS | K16: 0.1 | L16: 0.2 | M16: 0.01 | N16: 001W
A17: 6 | B17: PRS260510032 | C17: น็อตจับข้อต่อสายลม | D17: เหล็ก | E17: INTERNAL SERRATED LOCKING WASHER | F17: 805339139 + 453502192 | G17: XGA3252112202 | H17: 5 | I17: PCS | J17: 1 | K17: 0.1 | L17: 0.2 | M17: 0.01 | N17: 006W
A18: 7 | B18: PRS260510032 | C18: ข้อต่อวาล์ว | D18: เหล็ก | E18: END TYPE CONNECTOR+SEAL WASHER | F18: 453505137 + 805339161 | G18: XGA3250426060 | H18: 20 | I18: PCS | J18: 1 | K18: 1 | L18: 1 | M18: 0.01 | N18: 001W
A19: 8 | B19: PRS260510032 | C19: ข้อต่อวาล์ว(ตรง) | D19: เหล็ก | E19: HOLLOW BOLT+CIRCLIP+SPECIAL SECTION SEAL | F19: 453505138 + 453505139 + 453505140 | G19: XGA3250424070 | H19: 20 | I19: PCS | K19: 0.5 | L19: 0.5 | M19: 0.01 | N19: 001W
A20: 9 | B20: PRS260510032 | C20: ข้อต่อ(ตรง)หางไหลหม้อน้ำลมเบรค | D20: เหล็ก | E20: HOLLOW BOLT+CIRCLIP+SPECIAL SECTION SEAL | F20: 453505131 + 453505132 + 453505133 | G20: XGA3250416010 | H20: 50 | I20: PCS | K20: 1 | L20: 1 | M20: 0.01 | N20: 001W
A21: 10 | B21: PRS260510032 | C21: โช๊คอัพ | D21: เหล็ก | E21: SHOCK ABSORBER ASSEMBLY | F21: 452906971/XGA2921YPAY132-010 | G21: XGA3250376010 | H21: 4 | I21: PCS | K21: 12 | L21: 12 | M21: 0.02 | N21: 001W
A22: 11 | B22: PRS260510032 | C22: ขอบบังโคลนหน้าซ้าย | D22: เหล็ก | E22: LEFT FRONT FENDER ASSEMBLY | F22: 4584002159 | G22: XGA1150990400 | H22: 2 | I22: PCS | K22: 6 | L22: 6 | M22: 0.01 | N22: 001W
A23: 12 | B23: PRS260510032 | C23: ขอบบังโคลนหน้าขวา | D23: เหล็ก | E23: RIGHT FRONT FENDER ASSEMBLY | F23: 4584002158 | G23: XGA1150990100 | H23: 2 | I23: PCS | K23: 6 | L23: 6 | M23: 0.01 | N23: 001W
A24: 13 | B24: PRS260510032 | C24: เซ็นเซอร์อุณหภูมิ | D24: เหล็ก | E24: OUTDOOR TEMPERATURE SENSOR | F24: 458108684/XGA81AMSE111-030500 | G24: XGA1150690600 | H24: 2 | I24: PCS | K24: 0.1 | L24: 0.2 | M24: 0.01 | N24: 001W
A25: 14 | B25: PRS260510032 | C25: ชุดกระจังหน้า | D25: เหล็ก | E25: FRONT GRILLE ASSEMBLY INCLUDE FRONT LOGO ASSEMBLY | F25: 453906704 + 455312866 | G25: XGA1150690400 | H25: 3 | I25: PCS | J25: 1 | K25: 27 | L25: 27 | M25: 0.4 | N25: 006W
A26: 15 | B26: PRS260510032 | C26: แผงหน้าปัด | D26: เหล็ก | E26: FRONT PANEL ASSEMBLY | F26: 4553006658 | G26: XGA1150670200 | H26: 2 | I26: PCS | J26: 1 | K26: 7 | L26: 7 | M26: 0.01 | N26: 006W
A27: 16 | B27: PRS260510032 | C27: แก้มหน้าขวา | D27: เหล็ก | E27: RIGHT SIDE TRIM ASSEMBLY | F27: 4553006662 | G27: XGA1150670100 | H27: 2 | I27: PCS | J27: 1 | K27: 2 | L27: 2 | M27: 0.01 | N27: 001W
A28: 17 | B28: PRS260510032 | C28: ชุดลิมิตเตอร์ | D28: เหล็ก | E28: LIMITER ASSEMBLY | F28: 455019938/XGA50XEAW591-02111 | G28: XGA1150550700 | H28: 2 | I28: PCS | K28: 6 | L28: 6 | M28: 0.01 | N28: 001W
A29: 18 | B29: PRS260510032 | C29: เซ็นเซอร์แรงดันอากาศ | D29: เหล็ก | E29: AIR PRESSURE SENSOR | F29: 453808374/38HKFW211-30010 | G29: XGA1150457020 | H29: 4 | I29: PCS | K29: 0.1 | L29: 0.2 | M29: 0.01 | N29: 001W
A30: 19 | B30: PRS260510032 | C30: แผงคอยล์ร้อน | D30: เหล็ก | E30: CONDENSER ASSEMBLY | F30: 458108700/XGA81AMSE111-050100_ | G30: XGA1150439030 | H30: 3 | I30: PCS | K30: 9 | L30: 9 | M30: 0.03 | N30: 001W
A31: 20 | B31: PRS260510032 | C31: ท่อแรงดันต่ำสามทางถึงคอยล์เย็น | D31: เหล็ก | E31: LOW PRESSURE PIPE - T-JUNCTION TO EVAPORATOR SECTION | F31: 4581007526 | G31: XGA1150431140 | H31: 3 | I31: PCS | K31: 1 | L31: 1 | M31: 0.01 | N31: 001W
A32: 21 | B32: PRS260510032 | C32: สายจากคอนโทรลมือเข้าวาล์วแรงดัน | D32: เหล็ก | E32: HIGH-PRESSURE PIPE – VALVE STEAM SECTION | F32: 4581007525 | G32: XGA1150431100 | H32: 3 | I32: PCS | K32: 0.5 | L32: 0.5 | M32: 0.01 | N32: 001W
A33: 22 | B33: PRS260510032 | C33: ท่อแรงดันสูงวาล์วความเย็น | D33: เหล็ก | E33: HIGH PRESSURE PIPE - COOLING VALVE SECTION | F33: 4581007527 | G33: XGA1150431090 | H33: 3 | I33: PCS | K33: 0.5 | L33: 0.5 | M33: 0.01 | N33: 001W
A34: 23 | B34: PRS260510032 | C34: ช่องเสียบ USB | D34: เหล็ก | E34: USB INTERFACE | F34: 453717729/XGA37AMSN111-260200 | G34: XGA1150411030 | H34: 3 | I34: PCS | K34: 0.1 | L34: 0.2 | M34: 0.01 | N34: 001W
A35: 24 | B35: PRS260510032 | C35: ช่องจ่ายไฟ | D35: เหล็ก | E35: 24V POWER OUTLET | F35: 453717739/XGA37AMSN111-260400 | G35: XGA1150411020 | H35: 3 | I35: PCS | K35: 0.1 | L35: 0.2 | M35: 0.01 | N35: 001W
A36: 25 | B36: PRS260510032 | C36: ชุดสวิทซ์เปิด-ปิดกระจก | D36: เหล็ก | E36: ELECTRIC WINDOW MAIN SWITCH | F36: 453719236/XGA37AKSE111-460100 | G36: XGA1150399010 | H36: 3 | I36: PCS | K36: 0.1 | L36: 0.2 | M36: 0.01 | N36: 001W
A37: 26 | B37: PRS260510032 | C37: สวิทช์เกียร์ | D37: เหล็ก | E37: INTER-WHEEL DIFFERENTIAL LOCK SWITCH | F37: 459357670/XGA37AKSE111-920190 | G37: XGA1150387090 | H37: 5 | I37: PCS | K37: 0.1 | L37: 0.2 | M37: 0.01 | N37: 001W
A38: 27 | B38: PRS260510032 | C38: สวิทซ์เปิด-ปิดสัญญาณ | D38: เหล็ก | E38: LOW SPEED ALARM OFF SWITCH | F38: 459355728/ XGA37AKSE321-920210 | G38: XGA1150387080 | H38: 5 | I38: PCS | J38: 1 | K38: 0.1 | L38: 0.2 | M38: 0.01 | N38: 006W
A39: 28 | B39: PRS260510032 | C39: ข้อต่อไฮดรอลิค | D39: เหล็ก | E39: COMPRESSION FITTING PARTITIONED RIGHT ANGLE CONNECTOR BODY | F39: 819958812/Q81412 | G39: XGA1150357010 | H39: 20 | I39: PCS | J39: 1 | K39: 1 | L39: 1 | M39: 0.01 | N39: 001W
A40: 29 | B40: PRS260510032 | C40: ท่อกรองอากาศปั้มลมเข้าปั้มลม | D40: เหล็ก | E40: HIGH-TEMPERATURE RESISTANT PIPE ASSEMBLY | F40: 4535004234 | G40: XGA1150351010 | H40: 2 | I40: PCS | J40: 1 | K40: 0.5 | L40: 0.5 | M40: 0.01 | N40: 001W
...
